['multithreading.py', '4FAZA.fas', '4']
removed gaps!	 filt_gaps: 0.0011167526245117188 seconds
num cpus: 4
num_jobs:  4
[816 612 408 204]
processes initialized!
processes initialized!
processes initialized!
processes initialized!
Process Process-1:
Traceback (most recent call last):
  File "/n/app/python/3.6.0/lib/python3.6/multiprocessing/process.py", line 249, in _bootstrap
    self.run()
  File "/n/app/python/3.6.0/lib/python3.6/multiprocessing/process.py", line 93, in run
    self._target(*self._args, **self._kwargs)
TypeError: '_io.TextIOWrapper' object is not callable
Process Process-2:
Traceback (most recent call last):
  File "/n/app/python/3.6.0/lib/python3.6/multiprocessing/process.py", line 249, in _bootstrap
    self.run()
  File "/n/app/python/3.6.0/lib/python3.6/multiprocessing/process.py", line 93, in run
    self._target(*self._args, **self._kwargs)
TypeError: '_io.TextIOWrapper' object is not callable
Process Process-3:
Traceback (most recent call last):
  File "/n/app/python/3.6.0/lib/python3.6/multiprocessing/process.py", line 249, in _bootstrap
    self.run()
  File "/n/app/python/3.6.0/lib/python3.6/multiprocessing/process.py", line 93, in run
    self._target(*self._args, **self._kwargs)
TypeError: '_io.TextIOWrapper' object is not callable
Process Process-4:
Traceback (most recent call last):
  File "/n/app/python/3.6.0/lib/python3.6/multiprocessing/process.py", line 249, in _bootstrap
    self.run()
  File "/n/app/python/3.6.0/lib/python3.6/multiprocessing/process.py", line 93, in run
    self._target(*self._args, **self._kwargs)
TypeError: '_io.TextIOWrapper' object is not callable
output appended!
fast pdist implementation: 0.02567315101623535 seconds
